[2024-11-10 21:13:58,494][src.utils.utils][INFO] - [rank: 0] Enforcing tags! <cfg.extras.enforce_tags=True>
[2024-11-10 21:13:58,499][src.utils.utils][INFO] - [rank: 0] Printing config tree with Rich! <cfg.extras.print_config=True>
[2024-11-10 21:13:58,499][src.utils.rich_utils][WARNING] - [rank: 0] Field 'logger' not found in config. Skipping 'logger' config printing...
[2024-11-10 21:13:58,540][__main__][INFO] - [rank: 0] Instantiating datamodule <src.data.kinetics_datamodule.KineticsDataModule>
[2024-11-10 21:13:59,615][__main__][INFO] - [rank: 0] Instantiating model <src.models.vit_mae.VITModule>
[2024-11-10 21:14:02,386][__main__][INFO] - [rank: 0] Instantiating callbacks...
[2024-11-10 21:14:02,386][src.utils.instantiators][INFO] - [rank: 0] Instantiating callback <lightning.pytorch.callbacks.ModelCheckpoint>
[2024-11-10 21:14:02,389][src.utils.utils][ERROR] - [rank: 0] 
Traceback (most recent call last):
  File "/usr/local/anaconda3/envs/rlt/lib/python3.10/site-packages/hydra/_internal/utils.py", line 635, in _locate
    obj = import_module(part0)
  File "/usr/local/anaconda3/envs/rlt/lib/python3.10/importlib/__init__.py", line 126, in import_module
    return _bootstrap._gcd_import(name[level:], package, level)
  File "<frozen importlib._bootstrap>", line 1050, in _gcd_import
  File "<frozen importlib._bootstrap>", line 1027, in _find_and_load
  File "<frozen importlib._bootstrap>", line 1004, in _find_and_load_unlocked
ModuleNotFoundError: No module named 'lightning'

The above exception was the direct cause of the following exception:

Traceback (most recent call last):
  File "/usr/local/anaconda3/envs/rlt/lib/python3.10/site-packages/hydra/_internal/instantiate/_instantiate2.py", line 134, in _resolve_target
    target = _locate(target)
  File "/usr/local/anaconda3/envs/rlt/lib/python3.10/site-packages/hydra/_internal/utils.py", line 637, in _locate
    raise ImportError(
ImportError: Error loading 'lightning.pytorch.callbacks.ModelCheckpoint':
ModuleNotFoundError("No module named 'lightning'")
Are you sure that module 'lightning' is installed?

The above exception was the direct cause of the following exception:

Traceback (most recent call last):
  File "/home/rchoudhu/research/compressvit/pregrouping-release-debug/src/utils/utils.py", line 72, in wrap
    metric_dict, object_dict = task_func(cfg=cfg)
  File "/home/rchoudhu/research/compressvit/pregrouping-release-debug/src/train.py", line 66, in train
    callbacks: List[Callback] = instantiate_callbacks(cfg.get("callbacks"))
  File "/home/rchoudhu/research/compressvit/pregrouping-release-debug/src/utils/instantiators.py", line 31, in instantiate_callbacks
    callbacks.append(hydra.utils.instantiate(cb_conf))
  File "/usr/local/anaconda3/envs/rlt/lib/python3.10/site-packages/hydra/_internal/instantiate/_instantiate2.py", line 226, in instantiate
    return instantiate_node(
  File "/usr/local/anaconda3/envs/rlt/lib/python3.10/site-packages/hydra/_internal/instantiate/_instantiate2.py", line 333, in instantiate_node
    _target_ = _resolve_target(node.get(_Keys.TARGET), full_key)
  File "/usr/local/anaconda3/envs/rlt/lib/python3.10/site-packages/hydra/_internal/instantiate/_instantiate2.py", line 139, in _resolve_target
    raise InstantiationException(msg) from e
hydra.errors.InstantiationException: Error locating target 'lightning.pytorch.callbacks.ModelCheckpoint', set env var HYDRA_FULL_ERROR=1 to see chained exception.
full_key: callbacks.model_checkpoint
[2024-11-10 21:14:02,391][src.utils.utils][INFO] - [rank: 0] Output dir: /home/rchoudhu/research/compressvit/pregrouping-release-debug/logs/vitb_singlecrop/runs/2024-11-10_21-13-58
